Workbook

Sheet Sheet1
A1: catalog_number | B1: filter_id | C1: description | D1: filter_type | E1: supplier | F1: cut_on_nm | G1: cut_off_nm | H1: center_nm | I1: bandwidth_nm | J1: photo | K1: raw_file | L1: qrcode
A2: =CONCATENATE(D2,INT(F2),"-",INT(I2)) -> BS524-13 | B2: 1 | C2: Band-stop filter | D2: BS | E2: unknown | F2: 524.8 | G2: 538.47 | H2: =ROUND(AVERAGE(F2,G2),2) -> 531.64 | I2: =ROUND(ABS(F2-G2),2) -> 13.67 | K2: 1.txt | L2: =CONCATENATE(B2,".png") -> 1.png
A3: =CONCATENATE(D3,INT(F3),"-",INT(I3)) -> SP453-121 | B3: 2 | C3: Short Pass | D3: SP | E3: unknown | F3: 453.01 | G3: 574.37 | H3: =ROUND(AVERAGE(F3,G3),2) -> 513.69 | I3: =ROUND(ABS(F3-G3),2) -> 121.36 | K3: 2.txt | L3: =CONCATENATE(B3,".png") -> 2.png
A4: =CONCATENATE(D4,INT(F4),"-",INT(I4)) -> BP528-44 | B4: 3 | C4: Band Pass | D4: BP | E4: unknown | F4: 528.82 | G4: 573.37 | H4: =ROUND(AVERAGE(F4,G4),2) -> 551.1 | I4: =ROUND(ABS(F4-G4),2) -> 44.55 | K4: 3.txt | L4: =CONCATENATE(B4,".png") -> 3.png
A5: =CONCATENATE(D5,INT(F5),"-",INT(I5)) -> LP531-531 | B5: 4 | C5: Long Pass | D5: LP | E5: unknown | F5: 531.49 | H5: =ROUND(AVERAGE(F5,G5),2) -> 531.49 | I5: =ROUND(ABS(F5-G5),2) -> 531.49 | K5: 4.txt | L5: =CONCATENATE(B5,".png") -> 4.png
A6: =CONCATENATE(D6,INT(F6),"-",INT(I6)) -> BP539-11 | B6: 5 | C6: Band Pass | D6: BP | E6: unknown | F6: 539.8 | G6: 551 | H6: =ROUND(AVERAGE(F6,G6),2) -> 545.4 | I6: =ROUND(ABS(F6-G6),2) -> 11.2 | K6: 5.txt | L6: =CONCATENATE(B6,".png") -> 5.png
A7: =CONCATENATE(D7,INT(F7),"-",INT(I7)) -> LP610-610 | B7: 6 | C7: Long Pass | D7: LP | E7: unknown | F7: 610 | H7: =ROUND(AVERAGE(F7,G7),2) -> 610 | I7: =ROUND(ABS(F7-G7),2) -> 610 | K7: 6.txt | L7: =CONCATENATE(B7,".png") -> 6.png
A8: =CONCATENATE(D8,INT(F8),"-",INT(I8)) -> LP475-475 | B8: 7 | C8: Long Pass | D8: LP | E8: unknown | F8: 475.9 | H8: =ROUND(AVERAGE(F8,G8),2) -> 475.9 | I8: =ROUND(ABS(F8-G8),2) -> 475.9 | K8: 7.txt | L8: =CONCATENATE(B8,".png") -> 7.png
A9: =CONCATENATE(D9,INT(F9),"-",INT(I9)) -> CBC479-177 | B9: 8 | C9: Complex Band Cut | D9: CBC | E9: unknown | F9: 479 | G9: 656 | H9: =ROUND(AVERAGE(F9,G9),2) -> 567.5 | I9: =ROUND(ABS(F9-G9),2) -> 177 | K9: 8.txt | L9: =CONCATENATE(B9,".png") -> 8.png
A10: =CONCATENATE(D10,INT(F10),"-",INT(I10)) -> BP625-22 | B10: 9 | C10: Band Pass | D10: BP | E10: unknown | F10: 625.45 | G10: 648.39 | H10: =ROUND(AVERAGE(F10,G10),2) -> 636.92 | I10: =ROUND(ABS(F10-G10),2) -> 22.94 | K10: 9.txt | L10: =CONCATENATE(B10,".png") -> 9.png
A11: =CONCATENATE(D11,INT(F11),"-",INT(I11)) -> BP697-3 | B11: 10 | C11: Band Pass | D11: BP | E11: unknown | F11: 697.95 | G11: 701.03 | H11: =ROUND(AVERAGE(F11,G11),2) -> 699.49 | I11: =ROUND(ABS(F11-G11),2) -> 3.08 | K11: 10.txt | L11: =CONCATENATE(B11,".png") -> 10.png
A12: =CONCATENATE(D12,INT(F12),"-",INT(I12)) -> SP549-549 | B12: 11 | C12: Short Pass | D12: SP | E12: unknown | F12: 549.69 | H12: =ROUND(AVERAGE(F12,G12),2) -> 549.69 | I12: =ROUND(ABS(F12-G12),2) -> 549.69 | K12: 11.txt | L12: =CONCATENATE(B12,".png") -> 11.png
A13: =CONCATENATE(D13,INT(F13),"-",INT(I13)) -> BP658-15 | B13: 12 | C13: Band Pass | D13: BP | E13: unknown | F13: 658.47 | G13: 674.24 | H13: =ROUND(AVERAGE(F13,G13),2) -> 666.36 | I13: =ROUND(ABS(F13-G13),2) -> 15.77 | K13: 12.txt | L13: =CONCATENATE(B13,".png") -> 12.png
A14: =CONCATENATE(D14,INT(F14),"-",INT(I14)) -> Sp630-630 | B14: 13 | C14: Short Pass | D14: Sp | E14: unknown | F14: 630 | H14: =ROUND(AVERAGE(F14,G14),2) -> 630 | I14: =ROUND(ABS(F14-G14),2) -> 630 | K14: 13.txt | L14: =CONCATENATE(B14,".png") -> 13.png
A15: =CONCATENATE(D15,INT(F15),"-",INT(I15)) -> BP532-23 | B15: 14 | C15: Band Pass | D15: BP | E15: unknown | F15: 532.49 | G15: 556.24 | H15: =ROUND(AVERAGE(F15,G15),2) -> 544.37 | I15: =ROUND(ABS(F15-G15),2) -> 23.75 | K15: 14.txt | L15: =CONCATENATE(B15,".png") -> 14.png
A16: =CONCATENATE(D16,INT(F16),"-",INT(I16)) -> CBC506-184 | B16: 15 | C16: Complex Band Cut | D16: CBC | E16: unknown | F16: 506 | G16: 690 | H16: =ROUND(AVERAGE(F16,G16),2) -> 598 | I16: =ROUND(ABS(F16-G16),2) -> 184 | K16: 15.txt | L16: =CONCATENATE(B16,".png") -> 15.png
A17: =CONCATENATE(D17,INT(F17),"-",INT(I17)) -> LP545-545 | B17: 16 | C17: Long Pass | D17: LP | E17: unknown | F17: 545.42 | H17: =ROUND(AVERAGE(F17,G17),2) -> 545.42 | I17: =ROUND(ABS(F17-G17),2) -> 545.42 | K17: 16.txt | L17: =CONCATENATE(B17,".png") -> 16.png
A18: =CONCATENATE(D18,INT(F18),"-",INT(I18)) -> BP431-39 | B18: 17 | C18: Band Pass | D18: BP | E18: unknown | F18: 431.19 | G18: 470.28 | H18: =ROUND(AVERAGE(F18,G18),2) -> 450.74 | I18: =ROUND(ABS(F18-G18),2) -> 39.09 | K18: 17.txt | L18: =CONCATENATE(B18,".png") -> 17.png
A19: =CONCATENATE(D19,INT(F19),"-",INT(I19)) -> BP503-44 | B19: 18 | C19: Band Pass | D19: BP | E19: unknown | F19: 503.82 | G19: 548.05 | H19: =ROUND(AVERAGE(F19,G19),2) -> 525.94 | I19: =ROUND(ABS(F19-G19),2) -> 44.23 | K19: 18.txt | L19: =CONCATENATE(B19,".png") -> 18.png
A20: =CONCATENATE(D20,INT(F20),"-",INT(I20)) -> BP629-10 | B20: 19 | C20: Band Pass | D20: BP | E20: unknown | F20: 629.41 | G20: 640 | H20: =ROUND(AVERAGE(F20,G20),2) -> 634.71 | I20: =ROUND(ABS(F20-G20),2) -> 10.59 | K20: 19.txt | L20: =CONCATENATE(B20,".png") -> 19.png
A21: =CONCATENATE(D21,INT(F21),"-",INT(I21)) -> BP486-10 | B21: 20 | C21: Band Pass | D21: BP | E21: unknown | F21: 486.3 | G21: 496.63 | H21: =ROUND(AVERAGE(F21,G21),2) -> 491.47 | I21: =ROUND(ABS(F21-G21),2) -> 10.33 | K21: 20.txt | L21: =CONCATENATE(B21,".png") -> 20.png
A22: =CONCATENATE(D22,INT(F22),"-",INT(I22)) -> BP626-22 | B22: 21 | C22: Band Pass | D22: BP | E22: unknown | F22: 626.39 | G22: 648.39 | H22: =ROUND(AVERAGE(F22,G22),2) -> 637.39 | I22: =ROUND(ABS(F22-G22),2) -> 22 | K22: 21.txt | L22: =CONCATENATE(B22,".png") -> 21.png
A23: =CONCATENATE(D23,INT(F23),"-",INT(I23)) -> BP625-23 | B23: 22 | C23: Band Pass | D23: BP | E23: unknown | F23: 625.75 | G23: 648.86 | H23: =ROUND(AVERAGE(F23,G23),2) -> 637.31 | I23: =ROUND(ABS(F23-G23),2) -> 23.11 | K23: 22.txt | L23: =CONCATENATE(B23,".png") -> 22.png
A24: =CONCATENATE(D24,INT(F24),"-",INT(I24)) -> BP665-10 | B24: 23 | C24: Band Pass | D24: BP | E24: unknown | F24: 665.51 | G24: 676.27 | H24: =ROUND(AVERAGE(F24,G24),2) -> 670.89 | I24: =ROUND(ABS(F24-G24),2) -> 10.76 | K24: 23.txt | L24: =CONCATENATE(B24,".png") -> 23.png
A25: =CONCATENATE(D25,INT(F25),"-",INT(I25)) -> BP821-16 | B25: 24 | C25: Band Pass | D25: BP | E25: unknown | F25: 821.24 | G25: 837.53 | H25: =ROUND(AVERAGE(F25,G25),2) -> 829.39 | I25: =ROUND(ABS(F25-G25),2) -> 16.29 | K25: 24.txt | L25: =CONCATENATE(B25,".png") -> 24.png
A26: =CONCATENATE(D26,INT(F26),"-",INT(I26)) -> 0-0 | B26: 25 | E26: unknown | H26: =ROUND(AVERAGE(F26,G26),2) -> #DIV/0! | I26: =ROUND(ABS(F26-G26),2) -> 0 | K26: 25.txt | L26: =CONCATENATE(B26,".png") -> 25.png
A27: =CONCATENATE(D27,INT(F27),"-",INT(I27)) -> LP798-798 | B27: 26 | C27: Long Pass | D27: LP | E27: unknown | F27: 798 | H27: =ROUND(AVERAGE(F27,G27),2) -> 798 | I27: =ROUND(ABS(F27-G27),2) -> 798 | K27: 26.txt | L27: =CONCATENATE(B27,".png") -> 26.png
A28: =CONCATENATE(D28,INT(F28),"-",INT(I28)) -> LP423-423 | B28: 27 | C28: Long Pass | D28: LP | E28: unknown | F28: 423.6 | H28: =ROUND(AVERAGE(F28,G28),2) -> 423.6 | I28: =ROUND(ABS(F28-G28),2) -> 423.6 | K28: 27.txt | L28: =CONCATENATE(B28,".png") -> 27.png
A29: =CONCATENATE(D29,INT(F29),"-",INT(I29)) -> LP423-423 | B29: 28 | C29: Long Pass | D29: LP | E29: unknown | F29: 423.2 | H29: =ROUND(AVERAGE(F29,G29),2) -> 423.2 | I29: =ROUND(ABS(F29-G29),2) -> 423.2 | K29: 28.txt | L29: =CONCATENATE(B29,".png") -> 28.png
A30: =CONCATENATE(D30,INT(F30),"-",INT(I30)) -> LP796-796 | B30: 29 | C30: Long Pass | D30: LP | E30: unknown | F30: 796.68 | H30: =ROUND(AVERAGE(F30,G30),2) -> 796.68 | I30: =ROUND(ABS(F30-G30),2) -> 796.68 | K30: 29.txt | L30: =CONCATENATE(B30,".png") -> 29.png
A31: =CONCATENATE(D31,INT(F31),"-",INT(I31)) -> BP405-19 | B31: 30 | C31: Band Pass | D31: BP | E31: unknown | F31: 405.37 | G31: 424.69 | H31: =ROUND(AVERAGE(F31,G31),2) -> 415.03 | I31: =ROUND(ABS(F31-G31),2) -> 19.32 | K31: 30.txt | L31: =CONCATENATE(B31,".png") -> 30.png
A32: =CONCATENATE(D32,INT(F32),"-",INT(I32)) -> LP492-492 | B32: 31 | C32: Long Pass | D32: LP | E32: unknown | F32: 492.5 | H32: =ROUND(AVERAGE(F32,G32),2) -> 492.5 | I32: =ROUND(ABS(F32-G32),2) -> 492.5 | K32: 31.txt | L32: =CONCATENATE(B32,".png") -> 31.png
A33: =CONCATENATE(D33,INT(F33),"-",INT(I33)) -> LP676-676 | B33: 32 | C33: Long Pass | D33: LP | E33: unknown | F33: 676.27 | H33: =ROUND(AVERAGE(F33,G33),2) -> 676.27 | I33: =ROUND(ABS(F33-G33),2) -> 676.27 | K33: 32.txt | L33: =CONCATENATE(B33,".png") -> 32.png
A34: =CONCATENATE(D34,INT(F34),"-",INT(I34)) -> SP500-500 | B34: 33 | C34: Short Pass | D34: SP | E34: unknown | F34: 500 | H34: =ROUND(AVERAGE(F34,G34),2) -> 500 | I34: =ROUND(ABS(F34-G34),2) -> 500 | K34: 33.txt | L34: =CONCATENATE(B34,".png") -> 33.png
A35: =CONCATENATE(D35,INT(F35),"-",INT(I35)) -> SP531-531 | B35: 34 | C35: Short Pass | D35: SP | E35: unknown | F35: 531.36 | H35: =ROUND(AVERAGE(F35,G35),2) -> 531.36 | I35: =ROUND(ABS(F35-G35),2) -> 531.36 | K35: 34.txt | L35: =CONCATENATE(B35,".png") -> 34.png
A36: =CONCATENATE(D36,INT(F36),"-",INT(I36)) -> C403-403 | B36: 35 | C36: Complex | D36: C | E36: unknown | F36: 403 | H36: =ROUND(AVERAGE(F36,G36),2) -> 403 | I36: =ROUND(ABS(F36-G36),2) -> 403 | K36: D1.txt | L36: =CONCATENATE(B36,".png") -> 35.png
A37: =CONCATENATE(D37,INT(F37),"-",INT(I37)) -> LP560-560 | B37: 36 | C37: Long Pass | D37: LP | E37: unknown | F37: 560 | H37: =ROUND(AVERAGE(F37,G37),2) -> 560 | I37: =ROUND(ABS(F37-G37),2) -> 560 | K37: D2.txt | L37: =CONCATENATE(B37,".png") -> 36.png
A38: =CONCATENATE(D38,INT(F38),"-",INT(I38)) -> BC520-166 | B38: 37 | C38: Band Cut | D38: BC | E38: unknown | F38: 520 | G38: 686.6 | H38: =ROUND(AVERAGE(F38,G38),2) -> 603.3 | I38: =ROUND(ABS(F38-G38),2) -> 166.6 | K38: D3.txt | L38: =CONCATENATE(B38,".png") -> 37.png
A39: =CONCATENATE(D39,INT(F39),"-",INT(I39)) -> BC527-182 | B39: 38 | C39: Band Cut | D39: BC | E39: unknown | F39: 527.4 | G39: 710 | H39: =ROUND(AVERAGE(F39,G39),2) -> 618.7 | I39: =ROUND(ABS(F39-G39),2) -> 182.6 | K39: D4.txt | L39: =CONCATENATE(B39,".png") -> 38.png
A40: =CONCATENATE(D40,INT(F40),"-",INT(I40)) -> LP490-490 | B40: 39 | C40: Long Pass | D40: LP | E40: unknown | F40: 490 | H40: =ROUND(AVERAGE(F40,G40),2) -> 490 | I40: =ROUND(ABS(F40-G40),2) -> 490 | K40: D5.txt | L40: =CONCATENATE(B40,".png") -> 39.png
...

Sheet Sheet2
A1: catalog_number | B1: qr_code
A2: =Sheet1!A2 -> BS524-13 | B2: =Sheet1!L2 -> 1.png
A3: =Sheet1!A3 -> SP453-121 | B3: =Sheet1!L3 -> 2.png
A4: =Sheet1!A4 -> BP528-44 | B4: =Sheet1!L4 -> 3.png
A5: =Sheet1!A5 -> LP531-531 | B5: =Sheet1!L5 -> 4.png
A6: =Sheet1!A6 -> BP539-11 | B6: =Sheet1!L6 -> 5.png
A7: =Sheet1!A7 -> LP610-610 | B7: =Sheet1!L7 -> 6.png
A8: =Sheet1!A8 -> LP475-475 | B8: =Sheet1!L8 -> 7.png
A9: =Sheet1!A9 -> CBC479-177 | B9: =Sheet1!L9 -> 8.png
A10: =Sheet1!A10 -> BP625-22 | B10: =Sheet1!L10 -> 9.png
A11: =Sheet1!A11 -> BP697-3 | B11: =Sheet1!L11 -> 10.png
A12: =Sheet1!A12 -> SP549-549 | B12: =Sheet1!L12 -> 11.png
A13: =Sheet1!A13 -> BP658-15 | B13: =Sheet1!L13 -> 12.png
... A46: =Sheet1!A46 -> BC470-231 | B46: =Sheet1!L46 -> 45.png
